2025-04-19 01:34:44,393 - CRITICAL - ❌ خطا: 'list' object is not callable
Traceback (most recent call last):
  File "/home/runner/work/MihomoSaz/MihomoSaz/update_sublist.py", line 132, in <module>
    processor.generate_configs()
  File "/home/runner/work/MihomoSaz/MihomoSaz/update_sublist.py", line 126, in generate_configs
    self._generate_readme(list(merged.items()))
  File "/home/runner/work/MihomoSaz/MihomoSaz/update_sublist.py", line 77, in _generate_readme
    md_content([
TypeError: 'list' object is not callable
